{
 "cells": [
  {
   "attachments": {},
   "cell_type": "markdown",
   "metadata": {},
   "source": [
    "<h1 align='center'>Errors and Exception Handling</h1>"
   ]
  },
  {
   "attachments": {},
   "cell_type": "markdown",
   "metadata": {},
   "source": [
    "We will learn about Errors and Exception Handling in Python.\n",
    "\n",
    "For example:"
   ]
  },
  {
   "cell_type": "code",
   "execution_count": 1,
   "metadata": {},
   "outputs": [
    {
     "ename": "SyntaxError",
     "evalue": "EOL while scanning string literal (1679058590.py, line 1)",
     "output_type": "error",
     "traceback": [
      "\u001b[0;36m  Input \u001b[0;32mIn [1]\u001b[0;36m\u001b[0m\n\u001b[0;31m    print('Hello)\u001b[0m\n\u001b[0m                 ^\u001b[0m\n\u001b[0;31mSyntaxError\u001b[0m\u001b[0;31m:\u001b[0m EOL while scanning string literal\n"
     ]
    }
   ],
   "source": [
    "print('Hello)"
   ]
  },
  {
   "attachments": {},
   "cell_type": "markdown",
   "metadata": {},
   "source": [
    "Note how we get a SyntaxError, with the further description that it was an EOL (End of Line Error) while scanning the string literal. This is specific enough for us to see that we forgot a single quote at the end of the line. Understanding these various error types will help you debug your code much faster. "
   ]
  },
  {
   "attachments": {},
   "cell_type": "markdown",
   "metadata": {},
   "source": [
    "This type of error and description is known as an Exception. Even if a statement or expression is syntactically correct, it may cause an error when an attempt is made to execute it. Errors detected during execution are called exceptions and are not unconditionally fatal.\n",
    "\n",
    "You can check out the full list of built-in exceptions [here](https://docs.python.org/3/library/exceptions.html). "
   ]
  },
  {
   "attachments": {},
   "cell_type": "markdown",
   "metadata": {},
   "source": [
    "## try and except\n",
    "\n",
    "## try and except\n",
    "\n",
    "The basic terminology and syntax used to handle errors in Python are the <code>try</code> and <code>except</code> statements. The code which can cause an exception to occur is put in the <code>try</code> block and the handling of the exception is then implemented in the <code>except</code> block of code. \n",
    "\n",
    "The syntax follows:\n",
    "\n",
    "    try:\n",
    "       You do your operations here...\n",
    "       ...\n",
    "    except ExceptionI:\n",
    "       If there is ExceptionI, then execute this block.\n",
    "    except ExceptionII:\n",
    "       If there is ExceptionII, then execute this block.\n",
    "       ...\n",
    "    else:\n",
    "       If there is no exception then execute this block. \n",
    "\n",
    "We can also just check for any exception with just using <code>except:</code> \n",
    "\n",
    "To get a better understanding of all this let's check out an example:\n"
   ]
  },
  {
   "cell_type": "code",
   "execution_count": 2,
   "metadata": {},
   "outputs": [
    {
     "name": "stdout",
     "output_type": "stream",
     "text": [
      "Content written successfully\n"
     ]
    }
   ],
   "source": [
    "try:\n",
    "    f = open('testfile','w')\n",
    "    f.write('Test write this')\n",
    "except IOError:\n",
    "    # This will only check for an IOError exception and then execute this print statement\n",
    "    print(\"Error: Could not find file or read data\")\n",
    "else:\n",
    "    print(\"Content written successfully\")\n",
    "    f.close()"
   ]
  },
  {
   "attachments": {},
   "cell_type": "markdown",
   "metadata": {},
   "source": [
    "Now let's see what would happen if we did not have write permission (opening only with 'r'):"
   ]
  },
  {
   "cell_type": "code",
   "execution_count": 3,
   "metadata": {},
   "outputs": [
    {
     "name": "stdout",
     "output_type": "stream",
     "text": [
      "Error: Could not find file or read data\n"
     ]
    }
   ],
   "source": [
    "try:\n",
    "    f = open('testfile','r')\n",
    "    f.write('Test write this')\n",
    "except IOError:\n",
    "    # This will only check for an IOError exception and then execute this print statement\n",
    "    print(\"Error: Could not find file or read data\")\n",
    "else:\n",
    "    print(\"Content written successfully\")\n",
    "    f.close()"
   ]
  },
  {
   "attachments": {},
   "cell_type": "markdown",
   "metadata": {},
   "source": [
    "\n",
    "We could have also just said <code>except:</code> if we weren't sure what exception would occur. For example:"
   ]
  },
  {
   "cell_type": "code",
   "execution_count": 5,
   "metadata": {},
   "outputs": [
    {
     "name": "stdout",
     "output_type": "stream",
     "text": [
      "Error: Could not find file or read data\n"
     ]
    }
   ],
   "source": [
    "try:\n",
    "    f = open('testfile','r')\n",
    "    f.write('Test write this')\n",
    "except:\n",
    "    # This will check for any exception and then execute this print statement\n",
    "    print(\"Error: Could not find file or read data\")\n",
    "else:\n",
    "    print(\"Content written successfully\")\n",
    "    f.close()"
   ]
  },
  {
   "attachments": {},
   "cell_type": "markdown",
   "metadata": {},
   "source": [
    "If we want to keep to run code after the exception occurred we can use <code>finally</code>.\n",
    "\n",
    "The <code>finally:</code> block of code will always be run regardless if there was an exception in the <code>try</code> code block. The syntax is:\n",
    "\n",
    "    try:\n",
    "       Code block here\n",
    "       ...\n",
    "       Due to any exception, this code may be skipped!\n",
    "    finally:\n",
    "       This code block would always be executed.\n",
    "\n",
    "For example:"
   ]
  },
  {
   "attachments": {},
   "cell_type": "markdown",
   "metadata": {},
   "source": [
    "We can use this in conjunction with <code>except</code>. Let's see a new example that will take into account a user providing the wrong input:"
   ]
  },
  {
   "cell_type": "code",
   "execution_count": 8,
   "metadata": {},
   "outputs": [],
   "source": [
    "def askint():\n",
    "    try:\n",
    "        val = int(input(\"Please enter an integer: \"))\n",
    "    except:\n",
    "        print(\"Looks like you did not enter an integer!\")\n",
    "\n",
    "    finally:\n",
    "        print(\"Finally, I executed!\")\n",
    "    print(val)"
   ]
  },
  {
   "cell_type": "code",
   "execution_count": 9,
   "metadata": {},
   "outputs": [
    {
     "name": "stdout",
     "output_type": "stream",
     "text": [
      "Looks like you did not enter an integer!\n",
      "Finally, I executed!\n"
     ]
    },
    {
     "ename": "UnboundLocalError",
     "evalue": "local variable 'val' referenced before assignment",
     "output_type": "error",
     "traceback": [
      "\u001b[0;31m---------------------------------------------------------------------------\u001b[0m",
      "\u001b[0;31mUnboundLocalError\u001b[0m                         Traceback (most recent call last)",
      "\u001b[1;32m/Users/ajitkumarsingh/Desktop/Hands-on-with-Python/Errors and exception handling/errors_and_exception_handling.ipynb Cell 15\u001b[0m in \u001b[0;36m<cell line: 1>\u001b[0;34m()\u001b[0m\n\u001b[0;32m----> <a href='vscode-notebook-cell:/Users/ajitkumarsingh/Desktop/Hands-on-with-Python/Errors%20and%20exception%20handling/errors_and_exception_handling.ipynb#X21sZmlsZQ%3D%3D?line=0'>1</a>\u001b[0m askint()\n",
      "\u001b[1;32m/Users/ajitkumarsingh/Desktop/Hands-on-with-Python/Errors and exception handling/errors_and_exception_handling.ipynb Cell 15\u001b[0m in \u001b[0;36maskint\u001b[0;34m()\u001b[0m\n\u001b[1;32m      <a href='vscode-notebook-cell:/Users/ajitkumarsingh/Desktop/Hands-on-with-Python/Errors%20and%20exception%20handling/errors_and_exception_handling.ipynb#X21sZmlsZQ%3D%3D?line=6'>7</a>\u001b[0m \u001b[39mfinally\u001b[39;00m:\n\u001b[1;32m      <a href='vscode-notebook-cell:/Users/ajitkumarsingh/Desktop/Hands-on-with-Python/Errors%20and%20exception%20handling/errors_and_exception_handling.ipynb#X21sZmlsZQ%3D%3D?line=7'>8</a>\u001b[0m     \u001b[39mprint\u001b[39m(\u001b[39m\"\u001b[39m\u001b[39mFinally, I executed!\u001b[39m\u001b[39m\"\u001b[39m)\n\u001b[0;32m----> <a href='vscode-notebook-cell:/Users/ajitkumarsingh/Desktop/Hands-on-with-Python/Errors%20and%20exception%20handling/errors_and_exception_handling.ipynb#X21sZmlsZQ%3D%3D?line=8'>9</a>\u001b[0m \u001b[39mprint\u001b[39m(val)\n",
      "\u001b[0;31mUnboundLocalError\u001b[0m: local variable 'val' referenced before assignment"
     ]
    }
   ],
   "source": [
    "askint()"
   ]
  },
  {
   "attachments": {},
   "cell_type": "markdown",
   "metadata": {},
   "source": [
    "Notice how we got an error when trying to print val (because it was never properly assigned). Let's remedy this by asking the user and checking to make sure the input type is an integer:"
   ]
  },
  {
   "cell_type": "code",
   "execution_count": 12,
   "metadata": {},
   "outputs": [],
   "source": [
    "def askint():\n",
    "    try:\n",
    "        val = int(input(\"Please enter an integer: \"))\n",
    "    except:\n",
    "        print(\"Looks like you did not enter an integer!\")\n",
    "        val = int(input(\"Try again-Please enter an integer: \"))\n",
    "    finally:\n",
    "        print(\"Finally, I executed!\")\n",
    "    print(val)"
   ]
  },
  {
   "cell_type": "code",
   "execution_count": 14,
   "metadata": {},
   "outputs": [
    {
     "name": "stdout",
     "output_type": "stream",
     "text": [
      "Looks like you did not enter an integer!\n",
      "Finally, I executed!\n"
     ]
    },
    {
     "ename": "ValueError",
     "evalue": "invalid literal for int() with base 10: 'b'",
     "output_type": "error",
     "traceback": [
      "\u001b[0;31m---------------------------------------------------------------------------\u001b[0m",
      "\u001b[0;31mValueError\u001b[0m                                Traceback (most recent call last)",
      "\u001b[1;32m/Users/ajitkumarsingh/Desktop/Hands-on-with-Python/Errors and exception handling/errors_and_exception_handling.ipynb Cell 18\u001b[0m in \u001b[0;36maskint\u001b[0;34m()\u001b[0m\n\u001b[1;32m      <a href='vscode-notebook-cell:/Users/ajitkumarsingh/Desktop/Hands-on-with-Python/Errors%20and%20exception%20handling/errors_and_exception_handling.ipynb#X24sZmlsZQ%3D%3D?line=1'>2</a>\u001b[0m \u001b[39mtry\u001b[39;00m:\n\u001b[0;32m----> <a href='vscode-notebook-cell:/Users/ajitkumarsingh/Desktop/Hands-on-with-Python/Errors%20and%20exception%20handling/errors_and_exception_handling.ipynb#X24sZmlsZQ%3D%3D?line=2'>3</a>\u001b[0m     val \u001b[39m=\u001b[39m \u001b[39mint\u001b[39;49m(\u001b[39minput\u001b[39;49m(\u001b[39m\"\u001b[39;49m\u001b[39mPlease enter an integer: \u001b[39;49m\u001b[39m\"\u001b[39;49m))\n\u001b[1;32m      <a href='vscode-notebook-cell:/Users/ajitkumarsingh/Desktop/Hands-on-with-Python/Errors%20and%20exception%20handling/errors_and_exception_handling.ipynb#X24sZmlsZQ%3D%3D?line=3'>4</a>\u001b[0m \u001b[39mexcept\u001b[39;00m:\n",
      "\u001b[0;31mValueError\u001b[0m: invalid literal for int() with base 10: 'a'",
      "\nDuring handling of the above exception, another exception occurred:\n",
      "\u001b[0;31mValueError\u001b[0m                                Traceback (most recent call last)",
      "\u001b[1;32m/Users/ajitkumarsingh/Desktop/Hands-on-with-Python/Errors and exception handling/errors_and_exception_handling.ipynb Cell 18\u001b[0m in \u001b[0;36m<cell line: 1>\u001b[0;34m()\u001b[0m\n\u001b[0;32m----> <a href='vscode-notebook-cell:/Users/ajitkumarsingh/Desktop/Hands-on-with-Python/Errors%20and%20exception%20handling/errors_and_exception_handling.ipynb#X24sZmlsZQ%3D%3D?line=0'>1</a>\u001b[0m askint()\n",
      "\u001b[1;32m/Users/ajitkumarsingh/Desktop/Hands-on-with-Python/Errors and exception handling/errors_and_exception_handling.ipynb Cell 18\u001b[0m in \u001b[0;36maskint\u001b[0;34m()\u001b[0m\n\u001b[1;32m      <a href='vscode-notebook-cell:/Users/ajitkumarsingh/Desktop/Hands-on-with-Python/Errors%20and%20exception%20handling/errors_and_exception_handling.ipynb#X24sZmlsZQ%3D%3D?line=3'>4</a>\u001b[0m \u001b[39mexcept\u001b[39;00m:\n\u001b[1;32m      <a href='vscode-notebook-cell:/Users/ajitkumarsingh/Desktop/Hands-on-with-Python/Errors%20and%20exception%20handling/errors_and_exception_handling.ipynb#X24sZmlsZQ%3D%3D?line=4'>5</a>\u001b[0m     \u001b[39mprint\u001b[39m(\u001b[39m\"\u001b[39m\u001b[39mLooks like you did not enter an integer!\u001b[39m\u001b[39m\"\u001b[39m)\n\u001b[0;32m----> <a href='vscode-notebook-cell:/Users/ajitkumarsingh/Desktop/Hands-on-with-Python/Errors%20and%20exception%20handling/errors_and_exception_handling.ipynb#X24sZmlsZQ%3D%3D?line=5'>6</a>\u001b[0m     val \u001b[39m=\u001b[39m \u001b[39mint\u001b[39;49m(\u001b[39minput\u001b[39;49m(\u001b[39m\"\u001b[39;49m\u001b[39mTry again-Please enter an integer: \u001b[39;49m\u001b[39m\"\u001b[39;49m))\n\u001b[1;32m      <a href='vscode-notebook-cell:/Users/ajitkumarsingh/Desktop/Hands-on-with-Python/Errors%20and%20exception%20handling/errors_and_exception_handling.ipynb#X24sZmlsZQ%3D%3D?line=6'>7</a>\u001b[0m \u001b[39mfinally\u001b[39;00m:\n\u001b[1;32m      <a href='vscode-notebook-cell:/Users/ajitkumarsingh/Desktop/Hands-on-with-Python/Errors%20and%20exception%20handling/errors_and_exception_handling.ipynb#X24sZmlsZQ%3D%3D?line=7'>8</a>\u001b[0m     \u001b[39mprint\u001b[39m(\u001b[39m\"\u001b[39m\u001b[39mFinally, I executed!\u001b[39m\u001b[39m\"\u001b[39m)\n",
      "\u001b[0;31mValueError\u001b[0m: invalid literal for int() with base 10: 'b'"
     ]
    }
   ],
   "source": [
    "askint()"
   ]
  },
  {
   "attachments": {},
   "cell_type": "markdown",
   "metadata": {},
   "source": [
    "So why did our function print \"Finally, I executed!\" after each trial, yet it never printed `val` itself? \n",
    "\n",
    "- This is because with a try/except/finally clause, any <code>continue</code> or <code>break</code> statements are reserved until *after* the try clause is completed. \n",
    "- This means that even though a successful input of **3** brought us to the <code>else:</code> block, and a <code>break</code> statement was thrown, the try clause continued through to <code>finally:</code> before breaking out of the while loop. \n",
    "- And since <code>print(val)</code> was outside the try clause, the <code>break</code> statement prevented it from running."
   ]
  },
  {
   "cell_type": "code",
   "execution_count": 15,
   "metadata": {},
   "outputs": [],
   "source": [
    "def askint():\n",
    "    while True:\n",
    "        try:\n",
    "            val = int(input(\"Please enter an integer: \"))\n",
    "        except:\n",
    "            print(\"Looks like you did not enter an integer!\")\n",
    "            continue\n",
    "        else:\n",
    "            print(\"Yep that's an integer!\")\n",
    "            print(val)\n",
    "            break\n",
    "        finally:\n",
    "            print(\"Finally, I executed!\")"
   ]
  },
  {
   "cell_type": "code",
   "execution_count": 16,
   "metadata": {},
   "outputs": [
    {
     "name": "stdout",
     "output_type": "stream",
     "text": [
      "Looks like you did not enter an integer!\n",
      "Finally, I executed!\n",
      "Looks like you did not enter an integer!\n",
      "Finally, I executed!\n",
      "Looks like you did not enter an integer!\n",
      "Finally, I executed!\n",
      "Looks like you did not enter an integer!\n",
      "Finally, I executed!\n",
      "Looks like you did not enter an integer!\n",
      "Finally, I executed!\n",
      "Yep that's an integer!\n",
      "4\n",
      "Finally, I executed!\n"
     ]
    }
   ],
   "source": [
    "askint()"
   ]
  },
  {
   "cell_type": "code",
   "execution_count": null,
   "metadata": {},
   "outputs": [],
   "source": []
  }
 ],
 "metadata": {
  "kernelspec": {
   "display_name": "base",
   "language": "python",
   "name": "python3"
  },
  "language_info": {
   "codemirror_mode": {
    "name": "ipython",
    "version": 3
   },
   "file_extension": ".py",
   "mimetype": "text/x-python",
   "name": "python",
   "nbconvert_exporter": "python",
   "pygments_lexer": "ipython3",
   "version": "3.9.12"
  },
  "orig_nbformat": 4
 },
 "nbformat": 4,
 "nbformat_minor": 2
}
